<?xml version="1.0" ?>
<robot 
       xmlns:xacro="http://www.ros.org/wiki/xacro"
       name="adjustable_ft">


  <!-- basic ROS URDF model of the "adjustable-ft" six-axis force/torque sensor.
       The sensor is modeled using the two main only, namely upper-plate (robot side)
       and base-ring (tool side including spiral spring). The original 3D meshes
       are used for visualization, and two simple cylinders are used as collision
       models.

       By default, there is a static link in-between base-plate and tool-plate,
       but this could be changed to an (unacted) 6-DOF joint if you want to
       simulate realistic deflection under load. In this case you will also
       need a proper Gazebo physics simulation setup with controller configuration.

       Sensor size:
       d_outer2 = 104mm, h_inner = 18, h_outer = 15,  (base ring = tool plate)
       h_inner = 14 (upper plate = robot side)
       mass = ???

       The sensor URDF with base-plate, and tool-plate connected by a fixed joint.
       Note that the origin of the model is at the bottom of the *base_plate*,
       basically in the center of the sensor.
       Adjust the transformations from robot and to tool accordingly.
   -->

<!-- 
  <xacro:include filename="$(find tams_printed_ft)/urdf/ft_sensor.xacro" />
  <xacro:ft_control_plugin name="adjustable_ft" />
  <xacro:ft_sensor_plugin name="adjustable_ft" joint="${name}_fixed_joint" rate="200" topic="wrench" />
-->

<xacro:macro name="adjustable_ft" params="name" >

  <link name="${name}">
    <inertial>
      <origin xyz="0 0 ${0.014/2}" />
      <mass value="0.7" />
      <inertia  ixx="0.0001" ixy="0" ixz="0" iyy="0.0001" iyz="0" izz="0.00005" />
      </inertial>
      <visual>
        <origin xyz="0 0 ${-0.018}" />
        <material name="dummy" >
          <color rgba="0.5 0.9 0.5 1.0" />
        </material> 
        <geometry>
          <mesh filename="package://tams_printed_ft/meshes/adjustable_ft_upper_ring.dae" scale="0.001 0.001 0.001" />
        </geometry>
      </visual>
      <collision>
        <origin xyz="0 0 ${0.014/2}" />
        <geometry>
          <cylinder radius="${0.104/2}" length="0.014" />
        </geometry>
    </collision>
  </link>

  <gazebo reference="${name}">
      <material>Gazebo/Green</material>
      <turnGravityOff>false</turnGravityOff>
      <selfCollide>false</selfCollide>
      <!-- kp: stiffness kd: damping mu1, mu2: friction -->
      <mu1>100.0</mu1>
      <mu2>100.0</mu2>
      <kp>1000000.0</kp>
      <kd>1.0</kd>
  </gazebo>

  <link name="${name}_tool_ring">
    <inertial>
      <origin xyz="1 0 ${0.018/2}" />
      <mass value="0.15" />
      <inertia  ixx="0.00002" ixy="0" ixz="0" iyy="0.00002" iyz="0" izz="0.00001" />
    </inertial>
    <visual>
        <origin xyz="0 0 0" />
        <material name="silver" >
          <color rgba="0.9 0.9 0.9 1.0" />
        </material> 
        <geometry>
          <mesh filename="package://tams_printed_ft/meshes/adjustable_ft_base_ring.dae" scale="0.001 0.001 0.001" />
        </geometry>
      </visual>
      <collision>
        <origin xyz="0 0 ${0.016/2}" />
        <geometry>
          <cylinder radius="${0.104/2}" length="0.016" />
        </geometry>
      </collision>
  </link>

  <gazebo reference="${name}_tool_ring">
      <material>Gazebo/White</material>
      <turnGravityOff>false</turnGravityOff>
      <selfCollide>false</selfCollide>
      <!-- kp: stiffness kd: damping mu1, mu2: friction -->
      <mu1>100.0</mu1>
      <mu2>100.0</mu2>
      <kp>1000000.0</kp>
      <kd>1.0</kd>
  </gazebo>


  <!-- fucking controller requires a namespace followed by SLASH -->
  <!-- type=floating, no axis required -->
  <joint name="${name}_sensor_joint" type="revolute">
    <parent link="adjustable_ft" />
    <child link="adjustable_ft_tool_ring" />
    <origin xyz="0 0 ${-0.018}" rpy="0 0 0" />

    <axis xyz="1 0 0" rpy="0 0 0" />
    <dynamics damping="1.01" friction="0.05" />
    <limit lower="-0.02" upper="0.02" effort="100" velocity="1" />
    <safety_controller soft_lower_limit="-0.001" soft_upper_limit="0.001" k_position="1" k_velocity="1" /> 
  </joint>

  <transmission name="${name}_sensor_joint_transmission">
    <type>transmission_interface/SimpleTransmission</type>
    <joint name="${name}_sensor_joint">
      <hardwareInterface>hardware_interface/EffortJointInterface</hardwareInterface>
    </joint>
    <actuator name="${name}_sensor_joint_motor">
      <hardwareInterface>hardware_interface/EffortJointInterface</hardwareInterface>
      <mechanicalReduction>1</mechanicalReduction>
    </actuator>
  </transmission>


  <!-- <link name="${name}_tool_mount" /> -->
  <!--
  <joint name="${name}_tool_mount_joint" type="fixed">
    <parent link="adjustable_ft_tool_ring" />
    <child link="adjustable_ft_tool_mount" />
    <origin xyz="0 0 ${-0.018}" rpy="0 0 0" />
  </joint>
  -->

</xacro:macro>

</robot>
